<?xml version="1.0" ?>
<!-- =================================================================================== -->
<!-- |    This document was autogenerated by xacro from robit.xacro                    | -->
<!-- |    EDITING THIS FILE BY HAND IS NOT RECOMMENDED                                 | -->
<!-- =================================================================================== -->
<robot name="robit_urdf" xmlns:xacro="http://www.ros.org/wiki/xacro">
  <!-- Materials -->
  <material name="blue">
    <color rgba="0 0 0.8 1"/>
  </material>
  <material name="white">
    <color rgba="1 1 1 1"/>
  </material>
  <material name="gray">
    <color rgba="0.5 0.5 0.5 1"/>
  </material>
  <!-- Dimensions -->
  <link name="base_link">
    <visual>
      <geometry>
        <box size="0.095 0.07 0.008"/>
        <material name="gray"/>
      </geometry>
      <origin rpy="0 0 0" xyz="-0.0475 0 0"/>
      <!-- <origin rpy="0 0 0" xyz="0.0 0 0"/> -->
      <material name="gray"/>
    </visual>
    <collision>
      <geometry>
        <box size="0.095 0.07 0.008"/>
        <!-- <origin rpy="0 0 0" xyz="0 0 0"/> -->
      </geometry>
      <origin rpy="0 0 0" xyz="-0.0475 0 0"/>
    </collision>
    <!--	<xacro:default_inertial mass="0.001"/> -->
  </link>
  <link name="shoulder">
    <visual>
      <geometry>
        <cylinder length="0.038" radius="0.03"/>
      </geometry>
      <origin rpy="0 0 0" xyz="0 0 0.019"/>
      <material name="gray"/>
    </visual>
    <collision>
      <geometry>
        <cylinder length="0.038" radius="0.03"/>
      </geometry>
      <origin rpy="0 0 0" xyz="0 0 0.019"/>
    </collision>
    <inertial>
      <mass value="0.001"/>
      <inertia ixx="0.1" ixy="0.0" ixz="0.0" iyy="0.1" iyz="0.0" izz="0.1"/>
    </inertial>
  </link>
  <joint name="shoulder_rotate" type="revolute">
    <parent link="base_link"/>
    <child link="shoulder"/>
    <axis xyz="0 0 1"/>
    <!-- <origin xyz="0.0125 0 0.004"/> -->
    <origin xyz="-0.035 0 0.004"/>
    <limit effort="100.0" lower="-1.67552" upper="1.5708" velocity="10000000"/>
  </joint>
  <link name="second_base">
    <visual>
      <geometry>
        <box size="0.08 0.056 0.011"/>
      </geometry>
      <origin rpy="0 0 0" xyz="0 0 0.0055"/>
      <material name="gray"/>
    </visual>
    <collision>
      <geometry>
        <box size="0.08 0.056 0.011"/>
      </geometry>
      <origin rpy="0 0 0" xyz="0 0 0.0055"/>
    </collision>
    <inertial>
      <mass value="0.001"/>
      <inertia ixx="0.1" ixy="0.0" ixz="0.0" iyy="0.1" iyz="0.0" izz="0.1"/>
    </inertial>
  </link>
  <joint name="shoulder_to_second_base" type="fixed">
    <parent link="shoulder"/>
    <child link="second_base"/>
    <origin xyz="0 0 0.038"/>
  </joint>
  <link name="left_bracket">
    <visual>
      <geometry>
        <box size="0.085 0.006 0.08"/>
      </geometry>
      <origin rpy="0 0 0" xyz="0.02 0.003 0.04"/>
      <material name="blue"/>
    </visual>
    <collision>
      <geometry>
        <box size="0.085 0.006 0.08"/>
      </geometry>
      <origin rpy="0 0 0" xyz="0.02 0.003 0.04"/>
    </collision>
    <inertial>
      <mass value="0.001"/>
      <inertia ixx="0.1" ixy="0.0" ixz="0.0" iyy="0.1" iyz="0.0" izz="0.1"/>
    </inertial>
  </link>
  <joint name="second_base_to_left_bracket" type="fixed">
    <parent link="second_base"/>
    <child link="left_bracket"/>
    <origin xyz="0 0.028 0"/>
  </joint>
  <link name="right_bracket">
    <visual>
      <geometry>
        <box size="0.085 0.006 0.08"/>
      </geometry>
      <origin rpy="0 0 0" xyz="0.02 -0.003 0.04"/>
      <material name="gray"/>
    </visual>
    <collision>
      <geometry>
        <box size="0.085 0.006 0.08"/>
      </geometry>
      <origin rpy="0 0 0" xyz="0.02 -0.003 0.04"/>
    </collision>
    <inertial>
      <mass value="0.001"/>
      <inertia ixx="0.1" ixy="0.0" ixz="0.0" iyy="0.1" iyz="0.0" izz="0.1"/>
    </inertial>
  </link>
  <joint name="second_base_to_right_bracket" type="fixed">
    <parent link="second_base"/>
    <child link="right_bracket"/>
    <origin xyz="0 -0.028 0"/>
  </joint>
  <link name="upper_arm">
    <visual>
      <geometry>
        <box size="0.025 0.027 0.12"/>
      </geometry>
      <!-- <origin rpy="0 0 0" xyz="0 -0.024 0.0575"/> -->
      <origin rpy="0 0 0" xyz="0 -0.024 0.06"/>
      <material name="gray"/>
    </visual>
    <collision>
      <geometry>
        <box size="0.025 0.027 0.12"/>
      </geometry>
      <!-- <origin rpy="0 0 0" xyz="0 -0.024 0.0575"/> -->
      <origin rpy="0 0 0" xyz="0 -0.024 0.06"/>
    </collision>
    <inertial>
      <mass value="0.001"/>
      <inertia ixx="0.1" ixy="0.0" ixz="0.0" iyy="0.1" iyz="0.0" izz="0.1"/>
    </inertial>
  </link>
  <joint name="left_bracket_to_upper_arm" type="revolute">
    <parent link="left_bracket"/>
    <child link="upper_arm"/>
    <origin rpy="0 -1.36136 0" xyz="0.03 0 0.06"/>
    <axis xyz="0 1 0"/>
    <limit effort="100.0" lower="0" upper="2.58309" velocity="10000000"/>
  </joint>
  <link name="elbow">
    <visual>
      <geometry>
        <box size="0.07 0.036 0.042"/>
      </geometry>
      <origin xyz="-0.02 0 0.0125"/>
      <material name="gray"/>
    </visual>
    <collision>
      <geometry>
        <box size="0.07 0.036 0.042"/>
      </geometry>
      <origin xyz="-0.02 0 0.0125"/>
    </collision>
    <inertial>
      <mass value="0.001"/>
      <inertia ixx="0.1" ixy="0.0" ixz="0.0" iyy="0.1" iyz="0.0" izz="0.1"/>
    </inertial>
  </link>
  <joint name="elbow_joint" type="revolute">
    <parent link="upper_arm"/>
    <child link="elbow"/>
    <!-- <origin rpy="0 1.22173 0" xyz="0 -0.024 0.125"/> -->
    <origin rpy="0 1.22173 0" xyz="0 -0.024 0.12"/>
    <axis xyz="0 1 0"/>
    <limit effort="100.0" lower="-2.30383" upper="0" velocity="10000000"/>
  </joint>
  <link name="forearm">
    <visual>
      <geometry>
        <cylinder length="0.075" radius="0.01"/>
      </geometry>
      <origin rpy="0 1.5708 0" xyz="0.0375 0 0"/>
      <material name="white"/>
    </visual>
    <collision>
      <geometry>
        <cylinder length="0.075" radius="0.01"/>
      </geometry>
      <origin rpy="0 1.5708 0" xyz="0.0375 0 0"/>
    </collision>
    <inertial>
      <mass value="0.001"/>
      <inertia ixx="0.1" ixy="0.0" ixz="0.0" iyy="0.1" iyz="0.0" izz="0.1"/>
    </inertial>
  </link>
  <joint name="forearm_rotate" type="revolute">
    <parent link="elbow"/>
    <child link="forearm"/>
    <axis xyz="1 0 0"/>
    <origin xyz="0.015 0 0.02"/>
    <limit effort="100.0" lower="-1.88496" upper="1.53938" velocity="10000000"/>
  </joint>
  <link name="wrist">
    <visual>
      <geometry>
        <box size="0.05 0.038 0.03"/>
      </geometry>
      <origin xyz="0.025 0 0"/>
      <material name="gray"/>
    </visual>
    <collision>
      <geometry>
        <box size="0.05 0.038 0.03"/>
      </geometry>
      <origin xyz="0.025 0 0"/>
    </collision>
    <inertial>
      <mass value="0.001"/>
      <inertia ixx="0.1" ixy="0.0" ixz="0.0" iyy="0.1" iyz="0.0" izz="0.1"/>
    </inertial>
  </link>
  <joint name="forearm_to_wrist" type="fixed">
    <parent link="forearm"/>
    <child link="wrist"/>
    <origin xyz="0.075 0 0"/>
  </joint>
  <link name="hand">
    <visual>
      <geometry>
        <box size="0.03 0.02 0.025"/>
      </geometry>
      <origin xyz="0.01 0 0"/>
      <material name="blue"/>
    </visual>
    <collision>
      <geometry>
        <box size="0.03 0.02 0.025"/>
      </geometry>
      <origin xyz="0.01 0 0"/>
    </collision>
    <inertial>
      <mass value="0.001"/>
      <inertia ixx="0.1" ixy="0.0" ixz="0.0" iyy="0.1" iyz="0.0" izz="0.1"/>
    </inertial>
  </link>
  <joint name="wrist_joint" type="revolute">
    <parent link="wrist"/>
    <child link="hand"/>
    <axis xyz="0 1 0"/>
    <origin xyz="0.035 0 0"/>
    <!-- <limit effort="100.0" lower="-1.51536" upper="1.4784" velocity="10000000"/> -->
    <limit effort="100.0" lower="-1.423" upper="1.571" velocity="10000000"/>
  </joint>
  <link name="finger">
    <visual>
      <geometry>
        <cylinder length="0.003" radius="0.016"/>
      </geometry>
      <origin rpy="0 1.5708 0" xyz="0.002 0 0"/>
      <material name="gray"/>
    </visual>
    <collision>
      <geometry>
        <cylinder length="0.003" radius="0.016"/>
      </geometry>
      <origin rpy="0 1.5708 0" xyz="0.002 0 0"/>
    </collision>
    <inertial>
      <mass value="0.001"/>
      <inertia ixx="0.1" ixy="0.0" ixz="0.0" iyy="0.1" iyz="0.0" izz="0.1"/>
    </inertial>
  </link>
  <joint name="finger_rotate" type="revolute">
    <parent link="hand"/>
    <child link="finger"/>
    <axis xyz="1 0 0"/>
    <origin xyz="0.026 0 0"/>
    <!-- <limit effort="100.0" lower="-1.5708" upper="1.75559" velocity="10000000"/> -->
    <limit effort="100.0" lower="-1.2" upper="1.2" velocity="10000000"/>
  </joint>
  <link name="gripper">
    <visual>
      <geometry>
        <box size="0.13 0.112 0.016"/>
      </geometry>
      <origin xyz="0.065 0 0"/>
    </visual>
    <collision>
      <geometry>
        <box size="0.13 0.112 0.016"/>
      </geometry>
      <origin xyz="0.065 0 0"/>
    </collision>
    <inertial>
      <mass value="0.001"/>
      <inertia ixx="0.1" ixy="0.0" ixz="0.0" iyy="0.1" iyz="0.0" izz="0.1"/>
    </inertial>
  </link>
  <joint name="finger_to_gripper" type="fixed">
    <parent link="finger"/>
    <child link="gripper"/>
    <origin xyz="0.004 0 0"/>
  </joint>
  <link name="tip">
    <visual>
      <geometry>
        <box size="0.01 0.01 0.01"/>
      </geometry>
      <material name="white"/>
      <!-- <origin xyz="0.065 0 0"/> -->
      <origin xyz="0.0 0 0"/>
    </visual>
    <collision>
      <geometry>
        <box size="0.01 0.01 0.01"/>
      </geometry>
      <!-- <origin xyz="0.065 0 0"/> -->
      <origin xyz="0.0 0 0"/>
    </collision>
    <inertial>
      <mass value="0.001"/>
      <inertia ixx="0.1" ixy="0.0" ixz="0.0" iyy="0.1" iyz="0.0" izz="0.1"/>
    </inertial>
  </link>
  <joint name="gripper_to_tip" type="fixed">
    <parent link="gripper"/>
    <child link="tip"/>
    <origin xyz="0.13 0 0"/>
    <!-- <origin xyz="0.065 0 0"/> -->
  </joint>
</robot>

